Workbook
Name Categories: Lists!$B$2:$B$21
Name Category: Lists!#REF!
Name Cities: Lists!$A$2:$A$21
Name City: Lists!#REF!
Name Costumer_s_Name: Lists!$H$2:$H$21
Name Dicount: Lists!$I$2:$I$21
Name Payment_Methods: Lists!$G$2:$G$21
Name Product: Lists!#REF!
Name Products: Lists!$D$2:$D$21
Name Region: Lists!$C$2:$C$21
Name Salespersons: Lists!$F$2:$F$21
Name Slicer_Category: #N/A
Name Slicer_Payment_Method: #N/A
Name Slicer_Product: #N/A
Name Slicer_Region: #N/A
Name Slicer_Sales_person: #N/A
Name Unit_Price: Lists!#REF!

Sheet Lists
A1: Cities | B1: Categories | C1: Region | D1: Products | E1: Unit Price | F1: Salespersons | G1: Payment Methods | H1: Customer Names | I1: Discount
A2: Karachi | B2: Electronics | C2: East | D2: Laptop | E2: 85000 | F2: Ali | G2: Cash | H2: Ali Khan | I2: 0.2 | J2: Laptop | K2: Electronics
A3: Lahore | B3: Furniture | C3: West | D3: Monitor | E3: 30000 | F3: Ahmed | G3: Debit Card | H3: Ahmed Raza | I3: 0.05 | J3: Monitor | K3: Electronics | L3: Total Prices
A4: Islamabad | B4: Office Supplies | C4: South | D4: Keyboard | E4: 4000 | F4: Ayesha | G4: Credit Card | H4: Ayesha Malik | I4: 0.25 | J4: Keyboard | K4: Electronics
A5: Rawalpindi | C5: South East | D5: Mouse | E5: 2500 | F5: Fatima | G5: Bank Transfer | H5: Fatima Noor | I5: 0.1 | J5: Mouse | K5: Electronics
A6: Faisalabad | C6: South West | D6: Printer | E6: 28000 | F6: Hamza | H6: Hamza Ali | I6: 0.25 | J6: Printer | K6: Electronics
A7: Peshawar | C7: North | D7: Office Chair | E7: 12000 | F7: Bilal | H7: Sara Ahmed | I7: 0.15 | J7: Office Chair | K7: Furniture
A8: Multan | D8: Office Desk | E8: 22000 | F8: Zain | H8: Usman Khan | I8: 0.05 | J8: Office Desk | K8: Furniture
A9: Hyderabad | D9: Notebook | E9: 350 | F9: Sara | H9: Hina Shah | I9: 0.05 | J9: Notebook | K9: Office Supplies
A10: Quetta | D10: Printer Paper | E10: 1200 | F10: Usman | H10: Bilal Ahmed | I10: 0.15 | J10: Printer Paper | K10: Office Supplies
A11: Sialkot | D11: Calculator | E11: 1500 | F11: Hina | H11: Zain Malik | I11: 0.25 | J11: Calculator | K11: Office Supplies
D12: USB Drive | E12: 2000 | H12: Maham Khan | I12: 0.05 | J12: USB Drive | K12: Electronics
D13: Headphones | E13: 5000 | H13: Saad Raza | I13: 0.05 | J13: Headphones | K13: Electronics
H14: Sana Ali
H15: Hassan Ahmed
H16: Iqra Khan
H17: Danish Malik
H18: Mariam Noor
H19: Talha Ahmed
H20: Laiba Khan
H21: Owais Raza

Sheet Raw Data
A1: Order ID | B1: Order Date | C1: Customer Name | D1: City | E1: Region | F1: Product | G1: Category | H1: Quantity | I1: Unit Price | J1: Discount% | K1: Total Sales | L1: Sales person | M1: Payment Method | N1: Price Status
A2: ="ORD"&TEXT(ROW()-1,"0000") -> ORD0001 | B2: 45407 | C2: Usman Khan | D2: Quetta | E2: South West | F2: Office Desk | G2: =_xlfn.XLOOKUP(F2,Lists!$J$2:$J$13,Lists!$K$2:$K$13,"Not Found") -> Furniture | H2: 5 | I2: =_xlfn.XLOOKUP(F2,Lists!$D$2:$D$13,Lists!$E$2:$E$13,"Not Found") -> 22000 | J2: 0.25 | K2: =H2*I2*(1-J2) -> 82500 | L2: Ali | M2: Bank Transfer | N2: =IF(I2=_xlfn.XLOOKUP(F2,Lists!$D$2:$D$13,Lists!$E$2:$E$13,"Not Found"),"OK","Check Price") -> OK
A3: ="ORD"&TEXT(ROW()-1,"0000") -> ORD0002 | B3: 45729 | C3: Zain Malik | D3: Rawalpindi | E3: South | F3: Keyboard | G3: Electronics | H3: 6 | I3: 12000 | J3: 0.25 | K3: =H3*I3*(1-J3) -> 54000 | L3: Ayesha | M3: Debit Card | N3: =IF(I3=_xlfn.XLOOKUP(F3,Lists!$D$2:$D$13,Lists!$E$2:$E$13,"Not Found"),"OK","Check Price") -> Check Price
A4: ="ORD"&TEXT(ROW()-1,"0000") -> ORD0003 | B4: 45848 | C4: Saad Raza | D4: Sialkot | E4: North | F4: Mouse | G4: Furniture | H4: 6 | I4: 350 | J4: 0.05 | K4: =H4*I4*(1-J4) -> 1995 | L4: Zain | M4: Cash | N4: =IF(I4=_xlfn.XLOOKUP(F4,Lists!$D$2:$D$13,Lists!$E$2:$E$13,"Not Found"),"OK","Check Price") -> Check Price
A5: ="ORD"&TEXT(ROW()-1,"0000") -> ORD0004 | B5: 45400 | C5: Saad Raza | D5: Faisalabad | E5: South West | F5: Calculator | G5: =_xlfn.XLOOKUP(F5,Lists!$J$2:$J$13,Lists!$K$2:$K$13,"Not Found") -> Office Supplies | H5: 4 | I5: =_xlfn.XLOOKUP(F5,Lists!$D$2:$D$13,Lists!$E$2:$E$13,"Not Found") -> 1500 | J5: 0.15 | K5: =H5*I5*(1-J5) -> 5100 | L5: Ali | M5: Debit Card | N5: =IF(I5=_xlfn.XLOOKUP(F5,Lists!$D$2:$D$13,Lists!$E$2:$E$13,"Not Found"),"OK","Check Price") -> OK
A6: ="ORD"&TEXT(ROW()-1,"0000") -> ORD0005 | B6: 45506 | C6: Mariam Noor | D6: Hyderabad | E6: West | F6: Calculator | G6: =_xlfn.XLOOKUP(F6,Lists!$J$2:$J$13,Lists!$K$2:$K$13,"Not Found") -> Office Supplies | H6: 2 | I6: =_xlfn.XLOOKUP(F6,Lists!$D$2:$D$13,Lists!$E$2:$E$13,"Not Found") -> 1500 | J6: 0.1 | K6: =H6*I6*(1-J6) -> 2700 | L6: Ayesha | M6: Bank Transfer | N6: =IF(I6=_xlfn.XLOOKUP(F6,Lists!$D$2:$D$13,Lists!$E$2:$E$13,"Not Found"),"OK","Check Price") -> OK
A7: ="ORD"&TEXT(ROW()-1,"0000") -> ORD0006 | B7: 45477 | C7: Sara Ahmed | D7: Karachi | E7: West | F7: Monitor | G7: Office Supplies | H7: 6 | I7: 12000 | J7: 0.25 | K7: =H7*I7*(1-J7) -> 54000 | L7: Zain | M7: Bank Transfer | N7: =IF(I7=_xlfn.XLOOKUP(F7,Lists!$D$2:$D$13,Lists!$E$2:$E$13,"Not Found"),"OK","Check Price") -> Check Price
A8: ="ORD"&TEXT(ROW()-1,"0000") -> ORD0007 | B8: 45740 | C8: Owais Raza | D8: Peshawar | E8: South | F8: USB Drive | G8: Office Supplies | H8: 10 | I8: 22000 | J8: 0.2 | K8: =H8*I8*(1-J8) -> 176000 | L8: Bilal | M8: Bank Transfer | N8: =IF(I8=_xlfn.XLOOKUP(F8,Lists!$D$2:$D$13,Lists!$E$2:$E$13,"Not Found"),"OK","Check Price") -> Check Price
A9: ="ORD"&TEXT(ROW()-1,"0000") -> ORD0008 | B9: 45720 | C9: Danish Malik | D9: Rawalpindi | E9: South | F9: Laptop | G9: =_xlfn.XLOOKUP(F9,Lists!$J$2:$J$13,Lists!$K$2:$K$13,"Not Found") -> Electronics | H9: 5 | I9: =_xlfn.XLOOKUP(F9,Lists!$D$2:$D$13,Lists!$E$2:$E$13,"Not Found") -> 85000 | J9: 0.2 | K9: =H9*I9*(1-J9) -> 340000 | L9: Ali | M9: Cash | N9: =IF(I9=_xlfn.XLOOKUP(F9,Lists!$D$2:$D$13,Lists!$E$2:$E$13,"Not Found"),"OK","Check Price") -> OK
A10: ="ORD"&TEXT(ROW()-1,"0000") -> ORD0009 | B10: 45528 | C10: Iqra Khan | D10: Faisalabad | E10: South | F10: Calculator | G10: =_xlfn.XLOOKUP(F10,Lists!$J$2:$J$13,Lists!$K$2:$K$13,"Not Found") -> Office Supplies | H10: 7 | I10: =_xlfn.XLOOKUP(F10,Lists!$D$2:$D$13,Lists!$E$2:$E$13,"Not Found") -> 1500 | J10: 0.15 | K10: =H10*I10*(1-J10) -> 8925 | L10: Sara | M10: Debit Card | N10: =IF(I10=_xlfn.XLOOKUP(F10,Lists!$D$2:$D$13,Lists!$E$2:$E$13,"Not Found"),"OK","Check Price") -> OK
A11: ="ORD"&TEXT(ROW()-1,"0000") -> ORD0010 | B11: 45912 | C11: Saad Raza | D11: Lahore | E11: North | F11: Monitor | G11: Office Supplies | H11: 7 | I11: 85000 | J11: 0.25 | K11: =H11*I11*(1-J11) -> 446250 | L11: Ayesha | M11: Cash | N11: =IF(I11=_xlfn.XLOOKUP(F11,Lists!$D$2:$D$13,Lists!$E$2:$E$13,"Not Found"),"OK","Check Price") -> Check Price
A12: ="ORD"&TEXT(ROW()-1,"0000") -> ORD0011 | B12: 45533 | C12: Sana Ali | D12: Multan | E12: South East | F12: Office Desk | G12: =_xlfn.XLOOKUP(F12,Lists!$J$2:$J$13,Lists!$K$2:$K$13,"Not Found") -> Furniture | H12: 2 | I12: =_xlfn.XLOOKUP(F12,Lists!$D$2:$D$13,Lists!$E$2:$E$13,"Not Found") -> 22000 | J12: 0.2 | K12: =H12*I12*(1-J12) -> 35200 | L12: Ahmed | M12: Bank Transfer | N12: =IF(I12=_xlfn.XLOOKUP(F12,Lists!$D$2:$D$13,Lists!$E$2:$E$13,"Not Found"),"OK","Check Price") -> OK
A13: ="ORD"&TEXT(ROW()-1,"0000") -> ORD0012 | B13: 46005 | C13: Saad Raza | D13: Rawalpindi | E13: South East | F13: Notebook | G13: Office Supplies | H13: 1 | I13: 350 | J13: 0.1 | K13: =H13*I13*(1-J13) -> 315 | L13: Fatima | M13: Cash | N13: =IF(I13=_xlfn.XLOOKUP(F13,Lists!$D$2:$D$13,Lists!$E$2:$E$13,"Not Found"),"OK","Check Price") -> OK
A14: ="ORD"&TEXT(ROW()-1,"0000") -> ORD0013 | B14: 45356 | C14: Sara Ahmed | D14: Quetta | E14: West | F14: USB Drive | G14: Electronics | H14: 1 | I14: 1500 | J14: 0.2 | K14: =H14*I14*(1-J14) -> 1200 | L14: Ali | M14: Cash | N14: =IF(I14=_xlfn.XLOOKUP(F14,Lists!$D$2:$D$13,Lists!$E$2:$E$13,"Not Found"),"OK","Check Price") -> Check Price
A15: ="ORD"&TEXT(ROW()-1,"0000") -> ORD0014 | B15: 45365 | C15: Hamza Ali | D15: Hyderabad | E15: South East | F15: Headphones | G15: Office Supplies | H15: 5 | I15: 85000 | J15: 0.2 | K15: =H15*I15*(1-J15) -> 340000 | L15: Bilal | M15: Debit Card | N15: =IF(I15=_xlfn.XLOOKUP(F15,Lists!$D$2:$D$13,Lists!$E$2:$E$13,"Not Found"),"OK","Check Price") -> Check Price
A16: ="ORD"&TEXT(ROW()-1,"0000") -> ORD0015 | B16: 45779 | C16: Ali Khan | D16: Faisalabad | E16: South East | F16: Keyboard | G16: Electronics | H16: 6 | I16: 5000 | J16: 0.1 | K16: =H16*I16*(1-J16) -> 27000 | L16: Hamza | M16: Credit Card | N16: =IF(I16=_xlfn.XLOOKUP(F16,Lists!$D$2:$D$13,Lists!$E$2:$E$13,"Not Found"),"OK","Check Price") -> Check Price
A17: ="ORD"&TEXT(ROW()-1,"0000") -> ORD0016 | B17: 45912 | C17: Zain Malik | D17: Islamabad | E17: South West | F17: Office Desk | G17: =_xlfn.XLOOKUP(F17,Lists!$J$2:$J$13,Lists!$K$2:$K$13,"Not Found") -> Furniture | H17: 6 | I17: =_xlfn.XLOOKUP(F17,Lists!$D$2:$D$13,Lists!$E$2:$E$13,"Not Found") -> 22000 | J17: 0.15 | K17: =H17*I17*(1-J17) -> 112200 | L17: Ayesha | M17: Debit Card | N17: =IF(I17=_xlfn.XLOOKUP(F17,Lists!$D$2:$D$13,Lists!$E$2:$E$13,"Not Found"),"OK","Check Price") -> OK
A18: ="ORD"&TEXT(ROW()-1,"0000") -> ORD0017 | B18: 45374 | C18: Fatima Noor | D18: Quetta | E18: South | F18: Keyboard | G18: Office Supplies | H18: 9 | I18: 28000 | J18: 0.05 | K18: =H18*I18*(1-J18) -> 239400 | L18: Usman | M18: Cash | N18: =IF(I18=_xlfn.XLOOKUP(F18,Lists!$D$2:$D$13,Lists!$E$2:$E$13,"Not Found"),"OK","Check Price") -> Check Price
A19: ="ORD"&TEXT(ROW()-1,"0000") -> ORD0018 | B19: 45929 | C19: Hassan Ahmed | D19: Islamabad | E19: West | F19: Printer | G19: Electronics | H19: 8 | I19: 28000 | J19: 0.25 | K19: =H19*I19*(1-J19) -> 168000 | L19: Ayesha | M19: Credit Card | N19: =IF(I19=_xlfn.XLOOKUP(F19,Lists!$D$2:$D$13,Lists!$E$2:$E$13,"Not Found"),"OK","Check Price") -> OK
A20: ="ORD"&TEXT(ROW()-1,"0000") -> ORD0019 | B20: 45627 | C20: Iqra Khan | D20: Rawalpindi | E20: South West | F20: Printer Paper | G20: Office Supplies | H20: 2 | I20: 4000 | J20: 0.2 | K20: =H20*I20*(1-J20) -> 6400 | L20: Fatima | M20: Bank Transfer | N20: =IF(I20=_xlfn.XLOOKUP(F20,Lists!$D$2:$D$13,Lists!$E$2:$E$13,"Not Found"),"OK","Check Price") -> Check Price
A21: ="ORD"&TEXT(ROW()-1,"0000") -> ORD0020 | B21: 45401 | C21: Talha Ahmed | D21: Lahore | E21: South West | F21: Laptop | G21: =_xlfn.XLOOKUP(F21,Lists!$J$2:$J$13,Lists!$K$2:$K$13,"Not Found") -> Electronics | H21: 4 | I21: =_xlfn.XLOOKUP(F21,Lists!$D$2:$D$13,Lists!$E$2:$E$13,"Not Found") -> 85000 | J21: 0.2 | K21: =H21*I21*(1-J21) -> 272000 | L21: Fatima | M21: Debit Card | N21: =IF(I21=_xlfn.XLOOKUP(F21,Lists!$D$2:$D$13,Lists!$E$2:$E$13,"Not Found"),"OK","Check Price") -> OK
A22: ="ORD"&TEXT(ROW()-1,"0000") -> ORD0021 | B22: 45463 | C22: Danish Malik | D22: Islamabad | E22: North | F22: USB Drive | G22: Office Supplies | H22: 10 | I22: 12000 | J22: 0.05 | K22: =H22*I22*(1-J22) -> 114000 | L22: Zain | M22: Bank Transfer | N22: =IF(I22=_xlfn.XLOOKUP(F22,Lists!$D$2:$D$13,Lists!$E$2:$E$13,"Not Found"),"OK","Check Price") -> Check Price
A23: ="ORD"&TEXT(ROW()-1,"0000") -> ORD0022 | B23: 45633 | C23: Ahmed Raza | D23: Lahore | E23: West | F23: Office Desk | G23: =_xlfn.XLOOKUP(F23,Lists!$J$2:$J$13,Lists!$K$2:$K$13,"Not Found") -> Furniture | H23: 5 | I23: =_xlfn.XLOOKUP(F23,Lists!$D$2:$D$13,Lists!$E$2:$E$13,"Not Found") -> 22000 | J23: 0.2 | K23: =H23*I23*(1-J23) -> 88000 | L23: Sara | M23: Cash | N23: =IF(I23=_xlfn.XLOOKUP(F23,Lists!$D$2:$D$13,Lists!$E$2:$E$13,"Not Found"),"OK","Check Price") -> OK
A24: ="ORD"&TEXT(ROW()-1,"0000") -> ORD0023 | B24: 45770 | C24: Sana Ali | D24: Peshawar | E24: North | F24: Printer Paper | G24: Office Supplies | H24: 4 | I24: 30000 | J24: 0.1 | K24: =H24*I24*(1-J24) -> 108000 | L24: Bilal | M24: Cash | N24: =IF(I24=_xlfn.XLOOKUP(F24,Lists!$D$2:$D$13,Lists!$E$2:$E$13,"Not Found"),"OK","Check Price") -> Check Price
A25: ="ORD"&TEXT(ROW()-1,"0000") -> ORD0024 | B25: 45787 | C25: Mariam Noor | D25: Karachi | E25: South East | F25: Headphones | G25: Furniture | H25: 7 | I25: 1500 | J25: 0.2 | K25: =H25*I25*(1-J25) -> 8400 | L25: Ali | M25: Cash | N25: =IF(I25=_xlfn.XLOOKUP(F25,Lists!$D$2:$D$13,Lists!$E$2:$E$13,"Not Found"),"OK","Check Price") -> Check Price
A26: ="ORD"&TEXT(ROW()-1,"0000") -> ORD0025 | B26: 45965 | C26: Danish Malik | D26: Sialkot | E26: South West | F26: Office Desk | G26: =_xlfn.XLOOKUP(F26,Lists!$J$2:$J$13,Lists!$K$2:$K$13,"Not Found") -> Furniture | H26: 6 | I26: =_xlfn.XLOOKUP(F26,Lists!$D$2:$D$13,Lists!$E$2:$E$13,"Not Found") -> 22000 | J26: 0.25 | K26: =H26*I26*(1-J26) -> 99000 | L26: Ayesha | M26: Debit Card | N26: =IF(I26=_xlfn.XLOOKUP(F26,Lists!$D$2:$D$13,Lists!$E$2:$E$13,"Not Found"),"OK","Check Price") -> OK
A27: ="ORD"&TEXT(ROW()-1,"0000") -> ORD0026 | B27: 45517 | C27: Mariam Noor | D27: Lahore | E27: South West | F27: Printer | G27: Office Supplies | H27: 2 | I27: 30000 | J27: 0.25 | K27: =H27*I27*(1-J27) -> 45000 | L27: Ali | M27: Cash | N27: =IF(I27=_xlfn.XLOOKUP(F27,Lists!$D$2:$D$13,Lists!$E$2:$E$13,"Not Found"),"OK","Check Price") -> Check Price
A28: ="ORD"&TEXT(ROW()-1,"0000") -> ORD0027 | B28: 45382 | C28: Saad Raza | D28: Quetta | E28: South West | F28: Printer Paper | G28: Office Supplies | H28: 6 | I28: 4000 | J28: 0.15 | K28: =H28*I28*(1-J28) -> 20400 | L28: Hamza | M28: Bank Transfer | N28: =IF(I28=_xlfn.XLOOKUP(F28,Lists!$D$2:$D$13,Lists!$E$2:$E$13,"Not Found"),"OK","Check Price") -> Check Price
A29: ="ORD"&TEXT(ROW()-1,"0000") -> ORD0028 | B29: 45512 | C29: Mariam Noor | D29: Hyderabad | E29: West | F29: Office Desk | G29: =_xlfn.XLOOKUP(F29,Lists!$J$2:$J$13,Lists!$K$2:$K$13,"Not Found") -> Furniture | H29: 5 | I29: =_xlfn.XLOOKUP(F29,Lists!$D$2:$D$13,Lists!$E$2:$E$13,"Not Found") -> 22000 | J29: 0.1 | K29: =H29*I29*(1-J29) -> 99000 | L29: Fatima | M29: Cash | N29: =IF(I29=_xlfn.XLOOKUP(F29,Lists!$D$2:$D$13,Lists!$E$2:$E$13,"Not Found"),"OK","Check Price") -> OK
A30: ="ORD"&TEXT(ROW()-1,"0000") -> ORD0029 | B30: 45392 | C30: Danish Malik | D30: Hyderabad | E30: South West | F30: Monitor | G30: Office Supplies | H30: 1 | I30: 5000 | J30: 0.25 | K30: =H30*I30*(1-J30) -> 3750 | L30: Usman | M30: Cash | N30: =IF(I30=_xlfn.XLOOKUP(F30,Lists!$D$2:$D$13,Lists!$E$2:$E$13,"Not Found"),"OK","Check Price") -> Check Price
A31: ="ORD"&TEXT(ROW()-1,"0000") -> ORD0030 | B31: 45830 | C31: Saad Raza | D31: Sialkot | E31: South West | F31: Laptop | G31: =_xlfn.XLOOKUP(F31,Lists!$J$2:$J$13,Lists!$K$2:$K$13,"Not Found") -> Electronics | H31: 6 | I31: =_xlfn.XLOOKUP(F31,Lists!$D$2:$D$13,Lists!$E$2:$E$13,"Not Found") -> 85000 | J31: 0.1 | K31: =H31*I31*(1-J31) -> 459000 | L31: Usman | M31: Bank Transfer | N31: =IF(I31=_xlfn.XLOOKUP(F31,Lists!$D$2:$D$13,Lists!$E$2:$E$13,"Not Found"),"OK","Check Price") -> OK
A32: ="ORD"&TEXT(ROW()-1,"0000") -> ORD0031 | B32: 45331 | C32: Ayesha Malik | D32: Quetta | E32: South East | F32: Mouse | G32: Electronics | H32: 5 | I32: 12000 | J32: 0.25 | K32: =H32*I32*(1-J32) -> 45000 | L32: Fatima | M32: Credit Card | N32: =IF(I32=_xlfn.XLOOKUP(F32,Lists!$D$2:$D$13,Lists!$E$2:$E$13,"Not Found"),"OK","Check Price") -> Check Price
A33: ="ORD"&TEXT(ROW()-1,"0000") -> ORD0032 | B33: 45750 | C33: Ahmed Raza | D33: Quetta | E33: South West | F33: Mouse | G33: Office Supplies | H33: 1 | I33: 2500 | J33: 0.05 | K33: =H33*I33*(1-J33) -> 2375 | L33: Sara | M33: Cash | N33: =IF(I33=_xlfn.XLOOKUP(F33,Lists!$D$2:$D$13,Lists!$E$2:$E$13,"Not Found"),"OK","Check Price") -> OK
A34: ="ORD"&TEXT(ROW()-1,"0000") -> ORD0033 | B34: 45848 | C34: Mariam Noor | D34: Quetta | E34: West | F34: Printer | G34: Furniture | H34: 10 | I34: 22000 | J34: 0.2 | K34: =H34*I34*(1-J34) -> 176000 | L34: Bilal | M34: Cash | N34: =IF(I34=_xlfn.XLOOKUP(F34,Lists!$D$2:$D$13,Lists!$E$2:$E$13,"Not Found"),"OK","Check Price") -> Check Price
A35: ="ORD"&TEXT(ROW()-1,"0000") -> ORD0034 | B35: 45417 | C35: Danish Malik | D35: Faisalabad | E35: South West | F35: Notebook | G35: Furniture | H35: 4 | I35: 2500 | J35: 0.1 | K35: =H35*I35*(1-J35) -> 9000 | L35: Hina | M35: Cash | N35: =IF(I35=_xlfn.XLOOKUP(F35,Lists!$D$2:$D$13,Lists!$E$2:$E$13,"Not Found"),"OK","Check Price") -> Check Price
A36: ="ORD"&TEXT(ROW()-1,"0000") -> ORD0035 | B36: 45538 | C36: Bilal Ahmed | D36: Sialkot | E36: North | F36: Mouse | G36: Electronics | H36: 3 | I36: 2500 | J36: 0.1 | K36: =H36*I36*(1-J36) -> 6750 | L36: Sara | M36: Cash | N36: =IF(I36=_xlfn.XLOOKUP(F36,Lists!$D$2:$D$13,Lists!$E$2:$E$13,"Not Found"),"OK","Check Price") -> OK
A37: ="ORD"&TEXT(ROW()-1,"0000") -> ORD0036 | B37: 45863 | C37: Sana Ali | D37: Quetta | E37: East | F37: Printer | G37: Furniture | H37: 7 | I37: 12000 | J37: 0.05 | K37: =H37*I37*(1-J37) -> 79800 | L37: Fatima | M37: Credit Card | N37: =IF(I37=_xlfn.XLOOKUP(F37,Lists!$D$2:$D$13,Lists!$E$2:$E$13,"Not Found"),"OK","Check Price") -> Check Price
A38: ="ORD"&TEXT(ROW()-1,"0000") -> ORD0037 | B38: 45898 | C38: Ali Khan | D38: Faisalabad | E38: South West | F38: Laptop | G38: =_xlfn.XLOOKUP(F38,Lists!$J$2:$J$13,Lists!$K$2:$K$13,"Not Found") -> Electronics | H38: 8 | I38: =_xlfn.XLOOKUP(F38,Lists!$D$2:$D$13,Lists!$E$2:$E$13,"Not Found") -> 85000 | J38: 0.05 | K38: =H38*I38*(1-J38) -> 646000 | L38: Ahmed | M38: Credit Card | N38: =IF(I38=_xlfn.XLOOKUP(F38,Lists!$D$2:$D$13,Lists!$E$2:$E$13,"Not Found"),"OK","Check Price") -> OK
A39: ="ORD"&TEXT(ROW()-1,"0000") -> ORD0038 | B39: 45307 | C39: Hina Shah | D39: Rawalpindi | E39: East | F39: Notebook | G39: Electronics | H39: 5 | I39: 2500 | J39: 0.25 | K39: =H39*I39*(1-J39) -> 9375 | L39: Ali | M39: Bank Transfer | N39: =IF(I39=_xlfn.XLOOKUP(F39,Lists!$D$2:$D$13,Lists!$E$2:$E$13,"Not Found"),"OK","Check Price") -> Check Price
A40: ="ORD"&TEXT(ROW()-1,"0000") -> ORD0039 | B40: 45745 | C40: Danish Malik | D40: Peshawar | E40: South | F40: USB Drive | G40: Electronics | H40: 7 | I40: 30000 | J40: 0.25 | K40: =H40*I40*(1-J40) -> 157500 | L40: Usman | M40: Credit Card | N40: =IF(I40=_xlfn.XLOOKUP(F40,Lists!$D$2:$D$13,Lists!$E$2:$E$13,"Not Found"),"OK","Check Price") -> Check Price
...

Sheet Analysis
A1: Total Sales | B1: Total Orders | C1: Total Quantity | D1: Average Order Value
A2: =SUM(SalesData[Total Sales]) -> 1.0146586e+08 | B2: =COUNTA(SalesData[Order ID]) -> 1000 | C2: =SUM(SalesData[Quantity]) -> 5479 | D2: =A2/B2 -> 101465.86

Sheet Pivots
A1: Sales by Months | E1: Sales by Products | H1: Sales by SalesPerson Performance | K1: Sales by Region
A2: Years (Order Date) | B2: Months (Order Date) | C2: Sum of Total Sales | E2: Products | F2: Sum of Total Sales | H2: Sales Person | I2: Sum of Total Sales | K2: Region | L2: Sum of Total Sales
A3: 2024 | B3: Jan | C3: 2845590 | E3: Calculator | F3: 525000 | H3: Ahmed | I3: 8392347.5 | K3: East | L3: 20611850
B4: Feb | C4: 4937840 | E4: Headphones | F4: 7897787.5 | H4: Ali | I4: 16249705 | K4: North | L4: 15508848
B5: Mar | C5: 4619320 | E5: Keyboard | F5: 6567997.5 | H5: Ayesha | I5: 10631538 | K5: South | L5: 14372818
B6: Apr | C6: 5452800 | E6: Laptop | F6: 36222750 | H6: Bilal | I6: 8695777.5 | K6: South East | L6: 16387498
B7: May | C7: 3810852.5 | E7: Monitor | F7: 6006547.5 | H7: Fatima | I7: 10275082 | K7: West | L7: 16156142
B8: Jun | C8: 3921877.5 | E8: Mouse | F8: 6076387.5 | H8: Hamza | I8: 12407278 | K8: South West | L8: 18428702
B9: Jul | C9: 4318820 | E9: Notebook | F9: 5507170 | H9: Hina | I9: 9324817.5 | K9: Grand Total | L9: 1.0146586e+08
B10: Aug | C10: 9422005 | E10: Office Chair | F10: 6941902.5 | H10: Sara | I10: 6091995
B11: Sep | C11: 4090307.5 | E11: Office Desk | F11: 9735000 | H11: Usman | I11: 8404842.5 | K11: Sales by Category
B12: Oct | C12: 3211980 | E12: Printer | F12: 4929470 | H12: Zain | I12: 10992475 | K12: Category | L12: Sum of Total Sales
B13: Nov | C13: 3227587.5 | E13: Printer Paper | F13: 5659342.5 | H13: Grand Total | I13: 1.0146586e+08 | K13: Electronics | L13: 54927260
B14: Dec | C14: 5216190 | E14: USB Drive | F14: 5396502.5 | K14: Furniture | L14: 28693095
A15: 2024 Total | C15: 55075170 | E15: Grand Total | F15: 1.0146586e+08 | K15: Office Supplies | L15: 17845502
A16: 2025 | B16: Jan | C16: 4249992.5 | K16: Grand Total | L16: 1.0146586e+08
B17: Feb | C17: 3768090
B18: Mar | C18: 3061625
B19: Apr | C19: 4163080
B20: May | C20: 3576615
B21: Jun | C21: 2449110
B22: Jul | C22: 5823465
B23: Aug | C23: 2987350
B24: Sep | C24: 3604637.5
B25: Oct | C25: 4408370
B26: Nov | C26: 4759722.5
B27: Dec | C27: 3538630
A28: 2025 Total | C28: 46390688
A29: Grand Total | C29: 1.0146586e+08
A31: Total Sales | B31: Total ID's | C31: Order's Sold
A32: Sum of Total Sales | B32: Count of Order ID | C32: Sum of Quantity
A33: 1.0146586e+08 | B33: 1000 | C33: 5479

Sheet Dashboard
B2: SALES PERFORMANCE DASHBOARD
B4: Total Sales | D4: Total Quantity Sold
B5: =GETPIVOTDATA("Sum of Total Sales",Pivots!$A$32) -> 1.0146586e+08 | D5: =GETPIVOTDATA("Sum of Quantity",Pivots!$A$32) -> 5479
B7: Total Orders | D7: Average Order Value
B8: =GETPIVOTDATA("Count of Order ID",Pivots!$A$32) -> 1000 | D8: =GETPIVOTDATA("Sum of Total Sales",Pivots!$A$32)/GETPIVOTDATA("Count of Order ID",Pivots!$A$32) -> 101465.86

Sheet Insights & Recommendations
B2: Key Business Insights
B3: Overall Performance: The dashboard recorded total sales of 101.47 million across 1,000 orders, with 5,479 units sold and an average order value of 101,465.86.
B4: Yearly Comparison: Sales decreased from 55.08 million in 2024 to 46.39 million in 2025, a decline of approximately 15.77%.
B5: Category Performance: Electronics was the highest-selling category at 54.93 million, while Office Supplies recorded the lowest sales at 17.85 million.
B6: Product Performance: Laptop generated the highest product sales at 36.22 million, while Calculator recorded the lowest at 0.53 million.
B7: Regional Performance: East was the top-performing region with sales of 20.61 million, while South recorded the lowest regional sales at 14.37 million.
B8: Salesperson Performance: Ali generated the highest sales at 16.25 million, while Sara recorded the lowest at 6.09 million.
B9: Monthly Trends: August was the highest-sales month in 2024, while January was the lowest. In 2025, July was the highest-sales month and June was the lowest.
B10: Interactive Dashboard: Slicers for Category, Month, Product, Region, and Salesperson allow users to explore sales performance dynamically. KPI cards update with the selected filters.
B12: Business Recommendations
B13: Investigate the Year-over-Year Sales Decline: Compare monthly, product, and regional sales across 2024 and 2025 to identify where performance declined and which areas need further investigation.
B15: Analyze Regional Performance: Study the sales patterns and product mix in East, the highest-performing region, and investigate demand, product availability, and sales coverage in South, the lowest-performing region.
... B24: Use Interactive Reporting for Decisions: Regularly use the dashboard's KPI cards and slicers to monitor sales, orders, quantity sold, and average order value across products, regions, months, categories, and salespersons.
